<?xml version="1.0"?>
<robot xmlns:xacro="http://wiki.ros.org/xacro">

    <link name="left_wheel_link">
        <visual>
            <origin xyz="0 0 0" rpy="1.57079 0 0"/>
            <geometry>
                <cylinder length="0.04" radius="0.032"/>
            </geometry>
            <material name="black"/>
        </visual>

        <collision>
            <origin xyz="0 0 0" rpy="1.57079 0 0"/>
            <geometry>
                <cylinder length="0.04" radius="0.032"/>
            </geometry>
            <material name="black"/>
        </collision>

        <inertial>
            <mass value="0.2"/>
            <inertia ixx="0.00019041666667" ixy="0" ixz="0" iyy="0.0001904" iyz="0" izz="0.00036"/>
        </inertial>
    </link>

    <joint name="left_wheel_joint" type="continuous">
        <parent link="base_link" />
        <child link="left_wheel_link" />
        <origin xyz="-0.02 0.10 -0.06" />
        <axis xyz="0 1 0" />
    </joint>

    <link name="right_wheel_link">
        <visual>
            <origin xyz="0 0 0" rpy="1.57079 0 0"/>
            <geometry>
                <cylinder length="0.04" radius="0.032"/>
            </geometry>
            <material name="black"/>
        </visual>

        <collision>
            <origin xyz="0 0 0" rpy="1.57079 0 0"/>
            <geometry>
                <cylinder length="0.04" radius="0.032"/>
            </geometry>
            <material name="black"/>
        </collision>

        <inertial>
            <mass value="0.2"/>
            <inertia ixx="0.00019041666667" ixy="0" ixz="0" iyy="0.0001904" iyz="0" izz="0.00036"/>
        </inertial>
    </link>

    <joint name="right_wheel_joint" type="continuous">
        <parent link="base_link" />
        <child link="right_wheel_link" />
        <origin xyz="-0.02 -0.10 -0.06" />
        <axis xyz="0 1 0" />
    </joint>

    <link name="caster_link">
        <visual>
            <origin xyz="0 0 0" rpy="1.57079 0 0"/>
            <geometry>
                <sphere radius="0.016"/>
            </geometry>
            <material name="black"/>
        </visual>

        <collision>
            <origin xyz="0 0 0" rpy="1.57079 0 0"/>
            <geometry>
                <sphere radius="0.016"/>
            </geometry>
            <material name="black"/>
        </collision>

        <inertial>
            <mass value="0.02"/>
            <inertia ixx="0.00019041666667" ixy="0" ixz="0" iyy="0.0001904" iyz="0" izz="0.00036"/>
        </inertial>
    </link>

    <joint name="caster_joint" type="fixed">
        <parent link="base_link" />
        <child link="caster_link" />
        <origin xyz="0.06 0.0 -0.076" />
        <axis xyz="0 1 0" />
    </joint>

    <gazebo reference="caster_link">
        <material>Gazebo/Black</material>
    </gazebo>

    <gazebo reference="caster_link">
        <mu1 value="0.0"/>
        <mu2 value="0.0"/>
        <kp value="1000000.0" />
        <kd value="10.0" />
    </gazebo>

    <gazebo>
        <plugin name="diff_drive" filename="libgazebo_ros_diff_drive.so">
            <ros>
                <namespace>/</namespace>
                <remapping>cmd_vel:=cmd_vel</remapping>
                <remapping>odom:=odom</remapping>
            </ros>
            <update_rate>30</update_rate>
            <left_joint>left_wheel_joint</left_joint>
            <right_joint>right_wheel_joint</right_joint>
            <wheel_separation>0.2</wheel_separation>
            <wheel_diameter>0.065</wheel_diameter>
            <max_wheel_torque>20</max_wheel_torque>
            <max_wheel_acceleration>1.0</max_wheel_acceleration>
            <publish_odom>true</publish_odom>
            <publish_odom_tf>true</publish_odom_tf>
            <publish_wheel_tf>true</publish_wheel_tf>
            <odometry_frame>odom</odometry_frame>
            <robot_base_frame>base_footprint</robot_base_frame>
        </plugin>
    </gazebo>

</robot>